<?xml version="1.0" encoding="utf-8"?>
<robot xmlns:xacro="http://ros.org/wiki/xacro">
  <xacro:macro name="leg_right" params="leg_name parent pos_x pos_y pos_z roll pitch yaw">


    <!-- Base link -->
    <link name="${leg_name}_base_link">
      <inertial>
        <origin xyz="-0.00979014713716649 -0.00139011782449186 0.0218935307853371" rpy="0 0 0" />
        <mass value="0.0808021222974834" />
        <inertia ixx="1.27655E-05" ixy="5.10643E-13" ixz="-2.82428E-08" iyy="2.29991E-05" iyz="4.39699E-07" izz="1.62889E-05" />
      </inertial>
      <visual>
        <origin xyz="0 0 0" rpy="0 0 0" />
        <geometry>
          <mesh filename="package://elkapod_description/meshes/right_leg/base_link.STL" />
        </geometry>
        <material name="leg_black"/>
      </visual>
      <collision>
        <origin xyz="0 0 0" rpy="0 0 0" />
        <geometry>
          <mesh filename="package://elkapod_description/meshes/right_leg/base_link.STL" />
        </geometry>
      </collision>
    </link>

    <joint name="${leg_name}_base_joint" type="fixed">
        <origin xyz="${pos_x} ${pos_y} ${pos_z}" rpy="${roll} ${pitch} ${yaw}" />
        <parent link="${parent}" />
        <child link="${leg_name}_base_link" />
        <axis xyz="0 0 0" />
    </joint>

    <!-- Link A -->
    <link name="${leg_name}_linkA">
      <inertial>
        <origin xyz="0.0337988193565861 -0.000554586093327376 0.000549586085186449" rpy="0 0 0" />
        <mass value="0.0426933486153037" />
        <inertia ixx="1.98022E-05" ixy="-2.13458E-13" ixz="-5.41372E-13" iyy="1.670609E-05" iyz="-2.17248E-12" izz="1.67061E-05" />
      </inertial>
      <visual>
        <origin xyz="0 0 0" rpy="0 0 0" />
        <geometry>
          <mesh filename="package://elkapod_description/meshes/right_leg/linkA.STL" />
        </geometry>
        <material name="leg_black"/>
      </visual>
      <collision>
        <origin xyz="0 0 0" rpy="0 0 0" />
        <geometry>
          <mesh filename="package://elkapod_description/meshes/right_leg/linkA.STL" />
        </geometry>
      </collision>
    </link>

    <!-- Joint J1 -->
    <joint name="${leg_name}_J1" type="revolute">
        <origin xyz="0 0 0.02428" rpy="0 0 0" />
        <parent link="${leg_name}_base_link" />
        <child link="${leg_name}_linkA" />
        <axis xyz="0 0 1" />
        <limit lower="-1.57" upper="1.57" effort="50.0" velocity="7.3" />
    </joint>


    <!-- Link B -->
    <link name="${leg_name}_linkB">
      <inertial>
        <origin xyz="0.0461949754482681 0.00470912944794107 -0.00261992673183065" rpy="0 0 0" />
        <mass value="0.168678406706635" />
        <inertia ixx="2.79458E-05" ixy="8.13719E-13" ixz="2.16502E-12" iyy="4.53975E-05" iyz="-7.11437E-07" izz="3.38637E-05" />
      </inertial>
      <visual>
        <origin xyz="0 0 0" rpy="0 0 0" />
        <geometry>
          <mesh filename="package://elkapod_description/meshes/right_leg/linkB.STL" />
        </geometry>
        <material name="leg_black"/>
      </visual>
      <collision>
        <origin xyz="0 0 0" rpy="0 0 0" />
        <geometry>
          <mesh filename="package://elkapod_description/meshes/right_leg/linkB.STL" />
        </geometry>
      </collision>
    </link>

    <!-- Joint J2 -->
    <joint name="${leg_name}_J2" type="revolute">
        <origin xyz="0.0676 0 0" rpy="1.5708 0 0" />
        <parent link="${leg_name}_linkA" />
        <child link="${leg_name}_linkB" />
        <axis xyz="0 0 1" />
        <limit lower="-1.57" upper="1.57" effort="50.0" velocity="7.3" />
    </joint>

    <!-- Link C -->
    <link name="${leg_name}_linkC">
      <inertial>
        <origin xyz="0.0626878415018562 0.0138717503264788 0.00052553418423365" rpy="0 0 0" />
        <mass value="0.0457999682692435" />
        <inertia ixx="1.77293E-05" ixy="-3.34917E-06" ixz="3.26962E-07" iyy="6.16756E-05" iyz="6.79304E-08" izz="5.23429E-05" />
      </inertial>
      <visual>
        <origin xyz="0 0 0" rpy="0 0 0" />
        <geometry>
          <mesh filename="package://elkapod_description/meshes/right_leg/linkC.STL" />
        </geometry>
        <material name="orange_pla"/>
      </visual>
      <collision>
        <origin xyz="0 0 0" rpy="0 0 0" />
        <geometry>
          <mesh filename="package://elkapod_description/meshes/right_leg/linkC.STL" />
        </geometry>
      </collision>
    </link>

    <!-- Joint J3 -->
    <joint name="${leg_name}_J3" type="revolute">
        <origin xyz="0.092358 -0.0014421 0" rpy="0 0 0" />
        <parent link="${leg_name}_linkB" />
        <child link="${leg_name}_linkC" />
        <axis xyz="0 0 1" />
        <limit lower="-3.14" upper="3.14" effort="50.0" velocity="7.3" />
    </joint>

    <!-- FCP link -->
    <link name="${leg_name}_FCP">
      <inertial>
        <origin xyz="0.000341547110338625 4.16333634234434E-17 -3.46944695195361E-17" rpy="0 0 0" />
        <mass value="0.0111617991818567" />
        <inertia ixx="1.19862E-06" ixy="1.05879E-22" ixz="1.15499E-24" iyy="1.06703E-06" iyz="9.44775E-26" izz="1.06703E-06" />
      </inertial>
      <visual>
        <origin xyz="0 0 0" rpy="0 0 0" />
        <geometry>
          <sphere radius="0.01"/>
        </geometry>
        <material name="">
          <color rgba="1 0 0 1" />
        </material>
      </visual>
      <collision>
        <origin xyz="0 0 0" rpy="0 0 0" />
        <geometry>
          <sphere radius="0.01"/>
        </geometry>
      </collision>
    </link>

    <gazebo reference="${leg_name}_FCP">
      <mu1>10.0</mu1>
      <mu2>10.0</mu2>
    </gazebo>

    
    <gazebo reference="${leg_name}_FCP_joint">
        <sensor name="${leg_name}_fsr" type="force_torque">
          <always_on>true</always_on>
          <update_rate>100</update_rate>
          <visualize>true</visualize>
          <topic>/legs/${leg_name}/fsr</topic>
          <enable_metrics>true</enable_metrics>
          <pose>0 0 0 0 0 0</pose>
          <force_torque>
            <frame>sensor</frame>
            <measure_direction>child_to_parent</measure_direction>
          </force_torque> 
        </sensor>
    </gazebo>

    <!-- Fixed joint for FCP -->
    <joint name="${leg_name}_FCP_joint" type="prismatic">
        <origin xyz="0.213503787197785 0.00857470533092818 0" rpy="0 0 -0.294032099334707" />
        <parent link="${leg_name}_linkC" />
        <child link="${leg_name}_FCP" />
        <axis xyz="1 0 0" />
        <limit effort="1000.0" lower="-0.0001" upper="0.0001" velocity="30"/>
        <dynamics damping="10.0" friction="0.0"/>
    </joint>
  </xacro:macro>
</robot>