<?xml version="1.0" encoding="utf-8"?>
<robot xmlns:xacro="http://ros.org/wiki/xacro">
  <xacro:macro name="leg_left" params="leg_name parent pos_x pos_y pos_z roll pitch yaw">

    <!-- Base Link -->
    <link name="${leg_name}_base_link">
      <inertial>
        <origin xyz="-0.0097901 0.0013901 0.021894" rpy="0 0 0" />
        <mass value="0.080802" />
        <inertia ixx="1.2766E-05" ixy="5.3087E-13" ixz="-2.8241E-08" iyy="2.2999E-05" iyz="-4.397E-07" izz="1.6289E-05" />
      </inertial>
      <visual>
        <origin xyz="0 0 0" rpy="0 0 0" />
        <geometry>
          <mesh filename="package://elkapod_description/meshes/left_leg/base_link.STL" />
        </geometry>
        <material name="leg_black"/>
      </visual>
      <collision>
        <origin xyz="0 0 0" rpy="0 0 0" />
        <geometry>
          <mesh filename="package://elkapod_description/meshes/left_leg/base_link.STL" />
        </geometry>
      </collision>
    </link>
    
    <joint name="${leg_name}_base_joint" type="fixed">
      <origin xyz="${pos_x} ${pos_y} ${pos_z}" rpy="${roll} ${pitch} ${yaw}" />
      <parent link="${parent}" />
      <child link="${leg_name}_base_link" />
      <axis xyz="0 0 0" />
    </joint>

    <!-- Link A -->
    <link name="${leg_name}_linkA">
      <inertial>
        <origin xyz="0.033799 0.00051236 0.00054959" rpy="0 0 0" />
        <mass value="0.042693" />
        <inertia ixx="1.9802E-05" ixy="8.7559E-13" ixz="-5.8218E-13" iyy="1.6706E-05" iyz="-1.8291E-12" izz="1.6706E-05" />
      </inertial>
      <visual>
        <origin xyz="0 0 0" rpy="0 0 0" />
        <geometry>
          <mesh filename="package://elkapod_description/meshes/left_leg/linkA.STL" />
        </geometry>
        <material name="leg_black"/>
      </visual>
      <collision>
        <origin xyz="0 0 0" rpy="0 0 0" />
        <geometry>
          <mesh filename="package://elkapod_description/meshes/left_leg/linkA.STL" />
        </geometry>
      </collision>
    </link>

    <!-- Joint J1 -->
    <joint name="${leg_name}_J1" type="revolute">
      <origin xyz="0 0 0.02428" rpy="0 0 0" />
      <parent link="${leg_name}_base_link" />
      <child link="${leg_name}_linkA" />
      <axis xyz="0 0 1" />
      <limit lower="-1.57" upper="1.57" effort="50" velocity="7.3" />
    </joint>

    <!-- Link B -->
    <link name="${leg_name}_linkB">
      <inertial>
        <origin xyz="0.046185 0.0047076 0.0034661" rpy="0 0 0" />
        <mass value="0.16871" />
        <inertia ixx="2.7946E-05" ixy="-8.4625E-13" ixz="2.1218E-12" iyy="4.5398E-05" iyz="7.1144E-07" izz="3.3864E-05" />
      </inertial>
      <visual>
        <origin xyz="0 0 0" rpy="0 0 0" />
        <geometry>
          <mesh filename="package://elkapod_description/meshes/left_leg/linkB.STL" />
        </geometry>
        <material name="leg_black"/>
      </visual>
      <collision>
        <origin xyz="0 0 0" rpy="0 0 0" />
        <geometry>
          <mesh filename="package://elkapod_description/meshes/left_leg/linkB.STL" />
        </geometry>
      </collision>
    </link>

    <!-- Joint J2 -->
    <joint name="${leg_name}_J2" type="revolute">
      <origin xyz="0.0676 0 0" rpy="1.5708 0 0" />
      <parent link="${leg_name}_linkA" />
      <child link="${leg_name}_linkB" />
      <axis xyz="0 0 1" />
      <limit lower="-1.57" upper="1.57" effort="50" velocity="7.3" />
    </joint>

    <!-- Link C -->
    <link name="${leg_name}_linkC">
      <inertial>
        <origin xyz="0.062526 0.013836 -0.00039598" rpy="0 0 0" />
        <mass value="0.045919" />
        <inertia ixx="1.7731E-05" ixy="-3.3492E-06" ixz="3.2696E-07" iyy="6.1677E-05" iyz="6.793E-08" izz="5.2343E-05" />
      </inertial>
      <visual>
        <origin xyz="0 0 0" rpy="0 0 0" />
        <geometry>
          <mesh filename="package://elkapod_description/meshes/left_leg/linkC.STL" />
        </geometry>
        <material name="orange_pla"/>
      </visual>
      <collision>
        <origin xyz="0 0 0" rpy="0 0 0" />
        <geometry>
          <mesh filename="package://elkapod_description/meshes/left_leg/linkC.STL" />
        </geometry>
      </collision>
    </link>

    <!-- Joint J3 -->
    <joint name="${leg_name}_J3" type="revolute">
      <origin xyz="0.0923692721756408 0 0" rpy="0 0 0" />
      <parent link="${leg_name}_linkB" />
      <child link="${leg_name}_linkC" />
      <axis xyz="0 0 1" />
      <limit lower="-3.14" upper="1.57" effort="50" velocity="7.3" />
    </joint>

    <!-- FCP Link -->
    <link name="${leg_name}_FCP">
      <inertial>
        <origin xyz="0.000341547110339208 2.77555756156289E-17 1.73472347597681E-18" rpy="0 0 0" />
        <mass value="0.0111617991818567" />
        <inertia ixx="1.19862E-06" ixy="-5.67881E-40" ixz="-4.86711E-24" iyy="1.06703E-06" iyz="-1.94856E-26" izz="1.06703E-06" />
      </inertial>
      <visual>
        <origin xyz="0 0 0" rpy="0 0 0" />
        <geometry>
          <sphere radius="0.01"/>
        </geometry>
        <material name="">
          <color rgba="1 0 0 1" />
        </material>
      </visual>
      <collision>
        <origin xyz="0 0 0" rpy="0 0 0" />
        <geometry>
          <sphere radius="0.01"/>
        </geometry>
      </collision>
    </link>

    <gazebo reference="${leg_name}_FCP">
      <mu1>1000.0</mu1>
      <mu2>1000.0</mu2>
    </gazebo>
    
    <!-- Fixed Joint for FCP -->
    <joint name="${leg_name}_FCP_joint" type="fixed">
      <origin xyz="0.2135 0.0085747 0" rpy="0 0 -0.29403" />
      <parent link="${leg_name}_linkC" />
      <child link="${leg_name}_FCP" />
      <axis xyz="0 0 0" />
    </joint>
  </xacro:macro>
</robot>
